# Python Error and Exception Handling

Python provides a powerful mechanism for dealing with errors, known as **exceptions**. Exceptions allow your program to continue running even when unexpected situations arise. Instead of crashing, Python throws an exception, which can be caught and handled gracefully.

This guide covers the basics of error and exception handling in Python, including examples of how to use `try`, `except`, `else`, and `finally` blocks.

## What are Exceptions?

An **exception** is an event that disrupts the normal flow of a program's execution. It occurs when something goes wrong, like a division by zero, a missing file, or invalid input. Python has built-in exceptions, and you can also define your own.

### Example: Basic Exception

```python
try:
    x = 1 / 0  # This will raise a ZeroDivisionError
except ZeroDivisionError:
    print("You can't divide by zero!")
```

## Basic Try-Except

A `try` block contains the code that might raise an exception. If an exception occurs, the code in the corresponding `except` block will be executed.

### Example: Basic Try-Except

```python
try:
    number = int(input("Enter a number: "))  # Input could cause ValueError if not a number
except ValueError:
    print("That's not a valid number!")
```

## Handling Multiple Exceptions

You can handle different types of exceptions in separate `except` blocks. Each `except` block will handle a specific type of error.

### Example: Handling Multiple Exceptions

```python
try:
    x = int(input("Enter a number: "))  # User input might cause ValueError
    y = 10 / x  # Zero division can raise ZeroDivisionError
except ValueError:
    print("Invalid input! Please enter a number.")
except ZeroDivisionError:
    print("You can't divide by zero!")
```

## Using Else Block

The `else` block runs only if no exception is raised in the `try` block. It's used to define behavior when everything goes as expected.

### Example: Using Else Block

```python
try:
    number = int(input("Enter a number: "))
except ValueError:
    print("Invalid input!")
else:
    print(f"You entered the number: {number}")
```

## Using Finally Block

The `finally` block will always run, whether an exception occurs or not. It is typically used for cleanup operations, like closing files or releasing resources.

### Example: Using Finally Block

```python
try:
    file = open('data.txt', 'r')
    content = file.read()
except FileNotFoundError:
    print("File not found!")
finally:
    print("Closing the file...")
    file.close()  # This will always run
```

## Raising Exceptions

You can manually raise exceptions using the `raise` keyword. This is useful for enforcing custom conditions or raising specific error messages.

### Example: Raising Exceptions

```python
def check_age(age):
    if age < 18:
        raise ValueError("Age must be 18 or older!")  # Raising a custom exception with a message
    print("Age is valid")

try:
    check_age(16)
except ValueError as e:
    print(f"Error: {e}")
```

## Custom Exception Types (Without Using a Class)

In Python, you can raise custom exceptions without creating a custom class by simply using the built-in `Exception` class and passing a custom message to it. This allows you to define exceptions tailored to specific situations without the need for creating a new class.

### Example: Raising Custom Exception Without Class

```python
def check_age(age):
    if age < 18:
        raise Exception("Age must be 18 or older!")  # Raising a custom exception with a message
    print("Age is valid")

try:
    check_age(16)
except Exception as e:
    print(f"Error: {e}")
```

### Explanation:

- In this example, we're using Python's built-in `Exception` class to raise an exception with a custom error message. This is a quick way to implement custom exception handling when you don't need to create a full custom exception class.
- When the exception is raised (if the age is less than 18), it is caught in the `except` block, and the custom error message is printed.

## Catching Multiple Exceptions in One Line

You can catch multiple exceptions in a single `except` block by using a tuple. This can help reduce repetitive code when handling different types of exceptions similarly.

### Example: Catching Multiple Exceptions

```python
try:
    x = int(input("Enter a number: "))  # ValueError if not an integer
    y = 10 / x  # ZeroDivisionError if x is zero
except (ValueError, ZeroDivisionError) as e:
    print(f"Error: {e}")
```

## Using Assert

The `assert` statement tests a condition, and if the condition is `False`, it raises an `AssertionError`. This is commonly used for debugging and ensuring certain conditions are met during development.

### Example: Using Assert

```python
def check_positive(number):
    assert number > 0, "Number must be positive!"

try:
    check_positive(-10)
except AssertionError as e:
    print(f"Assertion Error: {e}")
```

## Catching All Exceptions (Not Recommended)

It is generally discouraged to catch all exceptions with a generic `except` block, as it can hide issues that should be addressed. It's better to catch specific exceptions to handle known error cases.

### Example: Catching All Exceptions

```python
try:
    x = int(input("Enter a number: "))  # Could cause ValueError
    y = 10 / x  # Could cause ZeroDivisionError
except Exception as e:  # Catching all exceptions (not ideal)
    print(f"An error occurred: {e}")
```

## Conclusion

Exception handling is a powerful feature in Python that allows you to build more resilient applications. By using `try`, `except`, `else`, and `finally`, you can manage errors effectively, provide meaningful feedback to users, and prevent your program from crashing.

Remember:

- **Use specific exceptions** to handle known error conditions.
- **Avoid catching all exceptions** unless absolutely necessary.
- **Use `finally` for cleanup operations** that must run regardless of errors.
